<?xml version="1.0"?>
<robot xmlns:xacro="http://www.ros.org/wiki/xacro">
  <!-- Macro for Roller Link and Joint -->
  <xacro:macro
    name="roller"
    params="name prefix parent_link x y z roll pitch yaw">
    <link name="${prefix}_${name}">
      <inertial>
        <!-- <origin xyz="0 0 0" rpy="0 0 0" /> -->
        <mass value="0.08" />
        <inertia ixx="7.0801668935833809126443849093065e-6" ixy="0.0" ixz="0.0"
          iyy="7.0801668935833809126443849093065e-6" iyz="0.0"
          izz="2.4266818920462031709780842373402e-6" />
      </inertial>
      <visual>
        <origin xyz="0 0 0" rpy="0 0 0" />
        <geometry>
          <mesh filename="package://car_4wd/meshes/roller.STL" />
        </geometry>
        <material name="">
          <color rgba="0.1 0.1 0.1 1" />
        </material>
      </visual>
      <collision>
        <!-- <origin xyz="0 0 0" rpy="0 0 0" /> -->
        <geometry>
          <mesh filename="package://car_4wd/meshes/roller.STL" />
        </geometry>
      </collision>
    </link>
    <joint name="${prefix}_${name}_joint" type="continuous">
      <origin xyz="${x} ${y} ${z}" rpy="${roll} ${pitch} ${yaw}" />
      <parent link="${parent_link}" />
      <child link="${prefix}_${name}" />
      <axis xyz="0 0 1" />
      <!-- <dynamics damping="0.01" friction="0.01" /> -->
    </joint>
  </xacro:macro>
</robot>